Workbook

Sheet README
A1: Bài 03 — Báo cáo doanh thu bằng IF, SUMIFS, COUNTIFS
A3: Nguồn dữ liệu | B3: Online Retail II (UCI Machine Learning Repository, Daqing Chen, 2019), https://archive.ics.uci.edu/dataset/502/online+retail+ii — giấy phép CC BY 4.0
A4: Trích mẫu | B4: 6810 dòng (mọi dòng, kể cả đơn huỷ và dòng điều chỉnh) của khách Germany và France, 01/09–30/11/2011, sheet 'Year 2010-2011', sắp theo InvoiceDate rồi Invoice.
A5: Giấy phép | B5: CC BY 4.0: được chia sẻ và chỉnh sửa, phải ghi nguồn như trên. Trích mẫu này chỉ để học.
A6: Quy ước | B6: Ô nền vàng là ô TODO: điền CÔNG THỨC (bắt đầu bằng =), không gõ số. Test đọc cả công thức lẫn giá trị.
A7: Lưu tệp | B7: LibreOffice: File > Save, chọn 'Use Excel 2007-365!' (giữ định dạng .xlsx). Excel: Ctrl+S.
A8: Chạy test | B8: uv run pytest <thư mục bài> -q (xem lệnh trong đề bài trên app)
A10: Việc cần làm | B10: 1. Sheet Data: điền công thức hàng 2 các cột I–L (ô vàng), kéo xuống hết bảng. Ô L2 so với A1 (tiêu đề) là đúng.
B11: 2. Sheet Report: ba bảng Doanh thu (B3:E5), Số đơn (B8:E10), AOV (B13:E15) và khối chỉ số H2:H8.
B12: 3. Doanh thu dùng định nghĩa chung của track: chỉ dòng hợp lệ, Quantity * Price.
B13: 4. Lưu .xlsx rồi chạy test.

Sheet Data
A1: Invoice | B1: StockCode | C1: Description | D1: Quantity | E1: InvoiceDate | F1: Price | G1: Customer ID | H1: Country | I1: Valid | J1: Revenue | K1: Month | L1: OrderStart
A2: C565085 | B2: 23079 | C2: TOADSTOOL BEDSIDE LIGHT | D2: -2 | E2: 40787.403 | F2: 8.95 | G2: 12474 | H2: Germany | I2: =IF(AND(LEFT(A2,1)<>"C",D2>0,F2>0),1,0) -> 0 | J2: =IF(I2=1,D2*F2,0) -> 0 | K2: =YEAR(E2)*100+MONTH(E2) -> 201109 | L2: =IF(AND(A2<>A1,LEFT(A2,1)<>"C"),1,0) -> 0
A3: C565089 | B3: 22553 | C3: PLASTERS IN TIN SKULLS | D3: -12 | E3: 40787.435 | F3: 1.65 | G3: 12645 | H3: Germany | I3: =IF(AND(LEFT(A3,1)<>"C",D3>0,F3>0),1,0) -> 0 | J3: =IF(I3=1,D3*F3,0) -> 0 | K3: =YEAR(E3)*100+MONTH(E3) -> 201109 | L3: =IF(AND(A3<>A2,LEFT(A3,1)<>"C"),1,0) -> 0
A4: C565227 | B4: 85053 | C4: FRENCH ENAMEL CANDLEHOLDER | D4: -1 | E4: 40788.379 | F4: 2.1 | G4: 12708 | H4: Germany | I4: =IF(AND(LEFT(A4,1)<>"C",D4>0,F4>0),1,0) -> 0 | J4: =IF(I4=1,D4*F4,0) -> 0 | K4: =YEAR(E4)*100+MONTH(E4) -> 201109 | L4: =IF(AND(A4<>A3,LEFT(A4,1)<>"C"),1,0) -> 0
A5: 565239 | B5: 85014A | C5: BLACK/BLUE POLKADOT UMBRELLA | D5: 6 | E5: 40788.41 | F5: 5.95 | G5: 12670 | H5: France | I5: =IF(AND(LEFT(A5,1)<>"C",D5>0,F5>0),1,0) -> 1 | J5: =IF(I5=1,D5*F5,0) -> 35.7 | K5: =YEAR(E5)*100+MONTH(E5) -> 201109 | L5: =IF(AND(A5<>A4,LEFT(A5,1)<>"C"),1,0) -> 1
A6: 565239 | B6: 21883 | C6: STARS GIFT TAPE | D6: 12 | E6: 40788.41 | F6: 0.65 | G6: 12670 | H6: France | I6: =IF(AND(LEFT(A6,1)<>"C",D6>0,F6>0),1,0) -> 1 | J6: =IF(I6=1,D6*F6,0) -> 7.8 | K6: =YEAR(E6)*100+MONTH(E6) -> 201109 | L6: =IF(AND(A6<>A5,LEFT(A6,1)<>"C"),1,0) -> 0
A7: 565239 | B7: 21881 | C7: CUTE CATS TAPE | D7: 12 | E7: 40788.41 | F7: 0.65 | G7: 12670 | H7: France | I7: =IF(AND(LEFT(A7,1)<>"C",D7>0,F7>0),1,0) -> 1 | J7: =IF(I7=1,D7*F7,0) -> 7.8 | K7: =YEAR(E7)*100+MONTH(E7) -> 201109 | L7: =IF(AND(A7<>A6,LEFT(A7,1)<>"C"),1,0) -> 0
A8: 565239 | B8: 21880 | C8: RED RETROSPOT TAPE | D8: 12 | E8: 40788.41 | F8: 0.65 | G8: 12670 | H8: France | I8: =IF(AND(LEFT(A8,1)<>"C",D8>0,F8>0),1,0) -> 1 | J8: =IF(I8=1,D8*F8,0) -> 7.8 | K8: =YEAR(E8)*100+MONTH(E8) -> 201109 | L8: =IF(AND(A8<>A7,LEFT(A8,1)<>"C"),1,0) -> 0
A9: 565239 | B9: 22991 | C9: GIRAFFE WOODEN RULER | D9: 12 | E9: 40788.41 | F9: 1.95 | G9: 12670 | H9: France | I9: =IF(AND(LEFT(A9,1)<>"C",D9>0,F9>0),1,0) -> 1 | J9: =IF(I9=1,D9*F9,0) -> 23.4 | K9: =YEAR(E9)*100+MONTH(E9) -> 201109 | L9: =IF(AND(A9<>A8,LEFT(A9,1)<>"C"),1,0) -> 0
A10: 565239 | B10: 22992 | C10: REVOLVER WOODEN RULER | D10: 12 | E10: 40788.41 | F10: 1.95 | G10: 12670 | H10: France | I10: =IF(AND(LEFT(A10,1)<>"C",D10>0,F10>0),1,0) -> 1 | J10: =IF(I10=1,D10*F10,0) -> 23.4 | K10: =YEAR(E10)*100+MONTH(E10) -> 201109 | L10: =IF(AND(A10<>A9,LEFT(A10,1)<>"C"),1,0) -> 0
A11: 565239 | B11: 22561 | C11: WOODEN SCHOOL COLOURING SET | D11: 12 | E11: 40788.41 | F11: 1.65 | G11: 12670 | H11: France | I11: =IF(AND(LEFT(A11,1)<>"C",D11>0,F11>0),1,0) -> 1 | J11: =IF(I11=1,D11*F11,0) -> 19.8 | K11: =YEAR(E11)*100+MONTH(E11) -> 201109 | L11: =IF(AND(A11<>A10,LEFT(A11,1)<>"C"),1,0) -> 0
A12: 565239 | B12: 22382 | C12: LUNCH BAG SPACEBOY DESIGN | D12: 10 | E12: 40788.41 | F12: 1.65 | G12: 12670 | H12: France | I12: =IF(AND(LEFT(A12,1)<>"C",D12>0,F12>0),1,0) -> 1 | J12: =IF(I12=1,D12*F12,0) -> 16.5 | K12: =YEAR(E12)*100+MONTH(E12) -> 201109 | L12: =IF(AND(A12<>A11,LEFT(A12,1)<>"C"),1,0) -> 0
A13: 565239 | B13: 22352 | C13: LUNCH BOX WITH CUTLERY RETROSPOT | D13: 12 | E13: 40788.41 | F13: 2.55 | G13: 12670 | H13: France | I13: =IF(AND(LEFT(A13,1)<>"C",D13>0,F13>0),1,0) -> 1 | J13: =IF(I13=1,D13*F13,0) -> 30.6 | K13: =YEAR(E13)*100+MONTH(E13) -> 201109 | L13: =IF(AND(A13<>A12,LEFT(A13,1)<>"C"),1,0) -> 0
... A4458: 574885 | B4458: POST | C4458: POSTAGE | D4458: 1 | E4458: 40854.584 | F4458: 18 | G4458: 12472 | H4458: Germany | I4458: =IF(AND(LEFT(A4458,1)<>"C",D4458>0,F4458>0),1,0) -> 1 | J4458: =IF(I4458=1,D4458*F4458,0) -> 18 | K4458: =YEAR(E4458)*100+MONTH(E4458) -> 201111 | L4458: =IF(AND(A4458<>A4457,LEFT(A4458,1)<>"C"),1,0) -> 0
A4459: 574918 | B4459: 22227 | C4459: HANGING HEART MIRROR DECORATION | D4459: 52 | E4459: 40854.688 | F4459: 0.65 | H4459: France | I4459: =IF(AND(LEFT(A4459,1)<>"C",D4459>0,F4459>0),1,0) -> 1 | J4459: =IF(I4459=1,D4459*F4459,0) -> 33.8 | K4459: =YEAR(E4459)*100+MONTH(E4459) -> 201111 | L4459: =IF(AND(A4459<>A4458,LEFT(A4459,1)<>"C"),1,0) -> 1
A4460: 574918 | B4460: 22602 | C4460: RETROSPOT WOODEN HEART DECORATION | D4460: 20 | E4460: 40854.688 | F4460: 0.85 | H4460: France | I4460: =IF(AND(LEFT(A4460,1)<>"C",D4460>0,F4460>0),1,0) -> 1 | J4460: =IF(I4460=1,D4460*F4460,0) -> 17 | K4460: =YEAR(E4460)*100+MONTH(E4460) -> 201111 | L4460: =IF(AND(A4460<>A4459,LEFT(A4460,1)<>"C"),1,0) -> 0
A4461: 574918 | B4461: 21818 | C4461: GLITTER HEART DECORATION | D4461: 20 | E4461: 40854.688 | F4461: 0.39 | H4461: France | I4461: =IF(AND(LEFT(A4461,1)<>"C",D4461>0,F4461>0),1,0) -> 1 | J4461: =IF(I4461=1,D4461*F4461,0) -> 7.8 | K4461: =YEAR(E4461)*100+MONTH(E4461) -> 201111 | L4461: =IF(AND(A4461<>A4460,LEFT(A4461,1)<>"C"),1,0) -> 0
A4462: 574918 | B4462: 22338 | C4462: STAR DECORATION PAINTED ZINC | D4462: 10 | E4462: 40854.688 | F4462: 0.19 | H4462: France | I4462: =IF(AND(LEFT(A4462,1)<>"C",D4462>0,F4462>0),1,0) -> 1 | J4462: =IF(I4462=1,D4462*F4462,0) -> 1.9 | K4462: =YEAR(E4462)*100+MONTH(E4462) -> 201111 | L4462: =IF(AND(A4462<>A4461,LEFT(A4462,1)<>"C"),1,0) -> 0
A4463: 574918 | B4463: 22219 | C4463: LOVEBIRD HANGING DECORATION WHITE | D4463: 32 | E4463: 40854.688 | F4463: 0.85 | H4463: France | I4463: =IF(AND(LEFT(A4463,1)<>"C",D4463>0,F4463>0),1,0) -> 1 | J4463: =IF(I4463=1,D4463*F4463,0) -> 27.2 | K4463: =YEAR(E4463)*100+MONTH(E4463) -> 201111 | L4463: =IF(AND(A4463<>A4462,LEFT(A4463,1)<>"C"),1,0) -> 0
A4464: 574918 | B4464: 22335 | C4464: HEART DECORATION PAINTED ZINC | D4464: 22 | E4464: 40854.688 | F4464: 0.65 | H4464: France | I4464: =IF(AND(LEFT(A4464,1)<>"C",D4464>0,F4464>0),1,0) -> 1 | J4464: =IF(I4464=1,D4464*F4464,0) -> 14.3 | K4464: =YEAR(E4464)*100+MONTH(E4464) -> 201111 | L4464: =IF(AND(A4464<>A4463,LEFT(A4464,1)<>"C"),1,0) -> 0
A4465: 574918 | B4465: 23201 | C4465: JUMBO BAG ALPHABET | D4465: 2 | E4465: 40854.688 | F4465: 2.08 | H4465: France | I4465: =IF(AND(LEFT(A4465,1)<>"C",D4465>0,F4465>0),1,0) -> 1 | J4465: =IF(I4465=1,D4465*F4465,0) -> 4.16 | K4465: =YEAR(E4465)*100+MONTH(E4465) -> 201111 | L4465: =IF(AND(A4465<>A4464,LEFT(A4465,1)<>"C"),1,0) -> 0
A4466: 574918 | B4466: 85136A | C4466: YELLOW SHARK HELICOPTER | D4466: 1 | E4466: 40854.688 | F4466: 7.95 | H4466: France | I4466: =IF(AND(LEFT(A4466,1)<>"C",D4466>0,F4466>0),1,0) -> 1 | J4466: =IF(I4466=1,D4466*F4466,0) -> 7.95 | K4466: =YEAR(E4466)*100+MONTH(E4466) -> 201111 | L4466: =IF(AND(A4466<>A4465,LEFT(A4466,1)<>"C"),1,0) -> 0
A4467: 574918 | B4467: 21822 | C4467: GLITTER CHRISTMAS TREE WITH BELLS | D4467: 12 | E4467: 40854.688 | F4467: 0.79 | H4467: France | I4467: =IF(AND(LEFT(A4467,1)<>"C",D4467>0,F4467>0),1,0) -> 1 | J4467: =IF(I4467=1,D4467*F4467,0) -> 9.48 | K4467: =YEAR(E4467)*100+MONTH(E4467) -> 201111 | L4467: =IF(AND(A4467<>A4466,LEFT(A4467,1)<>"C"),1,0) -> 0
A4468: 574918 | B4468: 22948 | C4468: METAL DECORATION NAUGHTY CHILDREN | D4468: 24 | E4468: 40854.688 | F4468: 0.85 | H4468: France | I4468: =IF(AND(LEFT(A4468,1)<>"C",D4468>0,F4468>0),1,0) -> 1 | J4468: =IF(I4468=1,D4468*F4468,0) -> 20.4 | K4468: =YEAR(E4468)*100+MONTH(E4468) -> 201111 | L4468: =IF(AND(A4468<>A4467,LEFT(A4468,1)<>"C"),1,0) -> 0
A4469: 574918 | B4469: 21811 | C4469: HANGING HEART WITH BELL | D4469: 48 | E4469: 40854.688 | F4469: 0.39 | H4469: France | I4469: =IF(AND(LEFT(A4469,1)<>"C",D4469>0,F4469>0),1,0) -> 1 | J4469: =IF(I4469=1,D4469*F4469,0) -> 18.72 | K4469: =YEAR(E4469)*100+MONTH(E4469) -> 201111 | L4469: =IF(AND(A4469<>A4468,LEFT(A4469,1)<>"C"),1,0) -> 0
A4470: 574918 | B4470: 84836 | C4470: ZINC METAL HEART DECORATION | D4470: 24 | E4470: 40854.688 | F4470: 1.25 | H4470: France | I4470: =IF(AND(LEFT(A4470,1)<>"C",D4470>0,F4470>0),1,0) -> 1 | J4470: =IF(I4470=1,D4470*F4470,0) -> 30 | K4470: =YEAR(E4470)*100+MONTH(E4470) -> 201111 | L4470: =IF(AND(A4470<>A4469,LEFT(A4470,1)<>"C"),1,0) -> 0
... A4489: 574918 | B4489: 23535 | C4489: WALL ART BICYCLE SAFETY | D4489: 1 | E4489: 40854.688 | F4489: 5.95 | H4489: France | I4489: =IF(AND(LEFT(A4489,1)<>"C",D4489>0,F4489>0),1,0) -> 1 | J4489: =IF(I4489=1,D4489*F4489,0) -> 5.95 | K4489: =YEAR(E4489)*100+MONTH(E4489) -> 201111 | L4489: =IF(AND(A4489<>A4488,LEFT(A4489,1)<>"C"),1,0) -> 0
A4490: C574946 | B4490: 22960 | C4490: JAM MAKING SET WITH JARS | D4490: -2 | E4490: 40855.372 | F4490: 4.25 | G4490: 12656 | H4490: France | I4490: =IF(AND(LEFT(A4490,1)<>"C",D4490>0,F4490>0),1,0) -> 0 | J4490: =IF(I4490=1,D4490*F4490,0) -> 0 | K4490: =YEAR(E4490)*100+MONTH(E4490) -> 201111 | L4490: =IF(AND(A4490<>A4489,LEFT(A4490,1)<>"C"),1,0) -> 0
A4491: 575049 | B4491: 22629 | C4491: SPACEBOY LUNCH BOX | D4491: 12 | E4491: 40855.509 | F4491: 1.95 | G4491: 12721 | H4491: France | I4491: =IF(AND(LEFT(A4491,1)<>"C",D4491>0,F4491>0),1,0) -> 1 | J4491: =IF(I4491=1,D4491*F4491,0) -> 23.4 | K4491: =YEAR(E4491)*100+MONTH(E4491) -> 201111 | L4491: =IF(AND(A4491<>A4490,LEFT(A4491,1)<>"C"),1,0) -> 1
A4492: 575049 | B4492: 22630 | C4492: DOLLY GIRL LUNCH BOX | D4492: 12 | E4492: 40855.509 | F4492: 1.95 | G4492: 12721 | H4492: France | I4492: =IF(AND(LEFT(A4492,1)<>"C",D4492>0,F4492>0),1,0) -> 1 | J4492: =IF(I4492=1,D4492*F4492,0) -> 23.4 | K4492: =YEAR(E4492)*100+MONTH(E4492) -> 201111 | L4492: =IF(AND(A4492<>A4491,LEFT(A4492,1)<>"C"),1,0) -> 0
A4493: 575049 | B4493: 23382 | C4493: BOX OF 6 CHRISTMAS CAKE DECORATIONS | D4493: 8 | E4493: 40855.509 | F4493: 3.75 | G4493: 12721 | H4493: France | I4493: =IF(AND(LEFT(A4493,1)<>"C",D4493>0,F4493>0),1,0) -> 1 | J4493: =IF(I4493=1,D4493*F4493,0) -> 30 | K4493: =YEAR(E4493)*100+MONTH(E4493) -> 201111 | L4493: =IF(AND(A4493<>A4492,LEFT(A4493,1)<>"C"),1,0) -> 0
A4494: 575049 | B4494: 23354 | C4494: 6 GIFT TAGS 50'S CHRISTMAS | D4494: 24 | E4494: 40855.509 | F4494: 0.83 | G4494: 12721 | H4494: France | I4494: =IF(AND(LEFT(A4494,1)<>"C",D4494>0,F4494>0),1,0) -> 1 | J4494: =IF(I4494=1,D4494*F4494,0) -> 19.92 | K4494: =YEAR(E4494)*100+MONTH(E4494) -> 201111 | L4494: =IF(AND(A4494<>A4493,LEFT(A4494,1)<>"C"),1,0) -> 0
A4495: 575049 | B4495: 23353 | C4495: 6 GIFT TAGS VINTAGE CHRISTMAS | D4495: 24 | E4495: 40855.509 | F4495: 0.83 | G4495: 12721 | H4495: France | I4495: =IF(AND(LEFT(A4495,1)<>"C",D4495>0,F4495>0),1,0) -> 1 | J4495: =IF(I4495=1,D4495*F4495,0) -> 19.92 | K4495: =YEAR(E4495)*100+MONTH(E4495) -> 201111 | L4495: =IF(AND(A4495<>A4494,LEFT(A4495,1)<>"C"),1,0) -> 0
A4496: 575049 | B4496: 22959 | C4496: WRAP CHRISTMAS VILLAGE | D4496: 25 | E4496: 40855.509 | F4496: 0.42 | G4496: 12721 | H4496: France | I4496: =IF(AND(LEFT(A4496,1)<>"C",D4496>0,F4496>0),1,0) -> 1 | J4496: =IF(I4496=1,D4496*F4496,0) -> 10.5 | K4496: =YEAR(E4496)*100+MONTH(E4496) -> 201111 | L4496: =IF(AND(A4496<>A4495,LEFT(A4496,1)<>"C"),1,0) -> 0
A4497: 575049 | B4497: 22778 | C4497: GLASS CLOCHE SMALL | D4497: 4 | E4497: 40855.509 | F4497: 3.95 | G4497: 12721 | H4497: France | I4497: =IF(AND(LEFT(A4497,1)<>"C",D4497>0,F4497>0),1,0) -> 1 | J4497: =IF(I4497=1,D4497*F4497,0) -> 15.8 | K4497: =YEAR(E4497)*100+MONTH(E4497) -> 201111 | L4497: =IF(AND(A4497<>A4496,LEFT(A4497,1)<>"C"),1,0) -> 0
A4498: 575049 | B4498: 47599B | C4498: BLUE PARTY BAGS | D4498: 6 | E4498: 40855.509 | F4498: 2.1 | G4498: 12721 | H4498: France | I4498: =IF(AND(LEFT(A4498,1)<>"C",D4498>0,F4498>0),1,0) -> 1 | J4498: =IF(I4498=1,D4498*F4498,0) -> 12.6 | K4498: =YEAR(E4498)*100+MONTH(E4498) -> 201111 | L4498: =IF(AND(A4498<>A4497,LEFT(A4498,1)<>"C"),1,0) -> 0
A4499: 575049 | B4499: 22331 | C4499: WOODLAND PARTY BAG + STICKER SET | D4499: 8 | E4499: 40855.509 | F4499: 1.65 | G4499: 12721 | H4499: France | I4499: =IF(AND(LEFT(A4499,1)<>"C",D4499>0,F4499>0),1,0) -> 1 | J4499: =IF(I4499=1,D4499*F4499,0) -> 13.2 | K4499: =YEAR(E4499)*100+MONTH(E4499) -> 201111 | L4499: =IF(AND(A4499<>A4498,LEFT(A4499,1)<>"C"),1,0) -> 0
A4500: 575049 | B4500: 22333 | C4500: RETROSPOT PARTY BAG + STICKER SET | D4500: 8 | E4500: 40855.509 | F4500: 1.65 | G4500: 12721 | H4500: France | I4500: =IF(AND(LEFT(A4500,1)<>"C",D4500>0,F4500>0),1,0) -> 1 | J4500: =IF(I4500=1,D4500*F4500,0) -> 13.2 | K4500: =YEAR(E4500)*100+MONTH(E4500) -> 201111 | L4500: =IF(AND(A4500<>A4499,LEFT(A4500,1)<>"C"),1,0) -> 0
A4501: 575049 | B4501: 23344 | C4501: JUMBO BAG 50'S CHRISTMAS | D4501: 10 | E4501: 40855.509 | F4501: 2.08 | G4501: 12721 | H4501: France | I4501: =IF(AND(LEFT(A4501,1)<>"C",D4501>0,F4501>0),1,0) -> 1 | J4501: =IF(I4501=1,D4501*F4501,0) -> 20.8 | K4501: =YEAR(E4501)*100+MONTH(E4501) -> 201111 | L4501: =IF(AND(A4501<>A4500,LEFT(A4501,1)<>"C"),1,0) -> 0
... A4877: 575750 | B4877: POST | C4877: POSTAGE | D4877: 3 | E4877: 40858.437 | F4877: 18 | G4877: 12600 | H4877: Germany | I4877: =IF(AND(LEFT(A4877,1)<>"C",D4877>0,F4877>0),1,0) -> 1 | J4877: =IF(I4877=1,D4877*F4877,0) -> 54 | K4877: =YEAR(E4877)*100+MONTH(E4877) -> 201111 | L4877: =IF(AND(A4877<>A4876,LEFT(A4877,1)<>"C"),1,0) -> 0
...

Sheet Report
A1: Doanh thu (GBP) — SUMIFS | G1: Chỉ số tổng quan
B2: 201109 | C2: 201110 | D2: 201111 | E2: Tổng 3 tháng | G2: Số dòng dữ liệu | H2: =COUNTA(Data!$A$2:$A$6811) -> 6810
A3: Germany | B3: =SUMIFS(Data!$J$2:$J$6811,Data!$H$2:$H$6811,$A3,Data!$K$2:$K$6811,B$2) -> 18091.22 | C3: =SUMIFS(Data!$J$2:$J$6811,Data!$H$2:$H$6811,$A3,Data!$K$2:$K$6811,C$2) -> 31638.42 | D3: =SUMIFS(Data!$J$2:$J$6811,Data!$H$2:$H$6811,$A3,Data!$K$2:$K$6811,D$2) -> 28025.02 | E3: =SUM(B3:D3) -> 77754.66 | G3: Số dòng hợp lệ | H3: =SUM(Data!$I$2:$I$6811) -> 6622
A4: France | B4: =SUMIFS(Data!$J$2:$J$6811,Data!$H$2:$H$6811,$A4,Data!$K$2:$K$6811,B$2) -> 23428.04 | C4: =SUMIFS(Data!$J$2:$J$6811,Data!$H$2:$H$6811,$A4,Data!$K$2:$K$6811,C$2) -> 33485.45 | D4: =SUMIFS(Data!$J$2:$J$6811,Data!$H$2:$H$6811,$A4,Data!$K$2:$K$6811,D$2) -> 31758.71 | E4: =SUM(B4:D4) -> 88672.2 | G4: Doanh thu TB mỗi dòng hợp lệ | H4: =AVERAGEIF(Data!$I$2:$I$6811,1,Data!$J$2:$J$6811) -> 25.132416
A5: Tổng | B5: =SUM(B3:B4) -> 41519.26 | C5: =SUM(C3:C4) -> 65123.87 | D5: =SUM(D3:D4) -> 59783.73 | E5: =SUM(E3:E4) -> 166426.86 | G5: Doanh thu dòng lớn nhất | H5: =MAX(Data!$J$2:$J$6811) -> 4161.06
A6: Số đơn — COUNTIFS trên OrderStart | G6: Ngày giao dịch đầu | H6: =MIN(Data!$E$2:$E$6811) -> 40787.403
B7: 201109 | C7: 201110 | D7: 201111 | E7: Tổng 3 tháng | G7: Ngày giao dịch cuối | H7: =MAX(Data!$E$2:$E$6811) -> 40877.699
A8: Germany | B8: =COUNTIFS(Data!$L$2:$L$6811,1,Data!$H$2:$H$6811,$A8,Data!$K$2:$K$6811,B$7) -> 41 | C8: =COUNTIFS(Data!$L$2:$L$6811,1,Data!$H$2:$H$6811,$A8,Data!$K$2:$K$6811,C$7) -> 58 | D8: =COUNTIFS(Data!$L$2:$L$6811,1,Data!$H$2:$H$6811,$A8,Data!$K$2:$K$6811,D$7) -> 68 | E8: =SUM(B8:D8) -> 167 | G8: Số dòng có Customer ID | H8: =COUNT(Data!$G$2:$G$6811) -> 6761
A9: France | B9: =COUNTIFS(Data!$L$2:$L$6811,1,Data!$H$2:$H$6811,$A9,Data!$K$2:$K$6811,B$7) -> 45 | C9: =COUNTIFS(Data!$L$2:$L$6811,1,Data!$H$2:$H$6811,$A9,Data!$K$2:$K$6811,C$7) -> 35 | D9: =COUNTIFS(Data!$L$2:$L$6811,1,Data!$H$2:$H$6811,$A9,Data!$K$2:$K$6811,D$7) -> 64 | E9: =SUM(B9:D9) -> 144
A10: Tổng | B10: =SUM(B8:B9) -> 86 | C10: =SUM(C8:C9) -> 93 | D10: =SUM(D8:D9) -> 132 | E10: =SUM(E8:E9) -> 311
A11: AOV = doanh thu / số đơn
B12: 201109 | C12: 201110 | D12: 201111 | E12: Tổng 3 tháng
A13: Germany | B13: =B3/B8 -> 441.24927 | C13: =C3/C8 -> 545.49 | D13: =D3/D8 -> 412.13265 | E13: =E3/E8 -> 465.59677
A14: France | B14: =B4/B9 -> 520.62311 | C14: =C4/C9 -> 956.72714 | D14: =D4/D9 -> 496.22984 | E14: =E4/E9 -> 615.77917
A15: Cả hai nước | B15: =B5/B10 -> 482.78209 | C15: =C5/C10 -> 700.25667 | D15: =D5/D10 -> 452.90705 | E15: =E5/E10 -> 535.1346
